<?xml version="1.0" encoding="UTF-8"?>
<!-- Generated by org.testng.reporters.JUnitXMLReporter -->
<testsuite hostname="PITTALA-DEV-L" failures="1" tests="5" name="Default test" time="0.021" errors="0" timestamp="28 May 2022 08:46:24 GMT">
  <testcase classname="packageTwo.PackageTwo_ClassTwo" name="login" time="0.007">
    <failure type="java.lang.AssertionError" message="expected object to not be null">
      <![CDATA[java.lang.AssertionError: expected object to not be null
	at org.testng.Assert.fail(Assert.java:94)
	at org.testng.Assert.assertNotNull(Assert.java:406)
	at org.testng.Assert.assertNotNull(Assert.java:391)
	at packageTwo.PackageTwo_ClassTwo.login(PackageTwo_ClassTwo.java:15)
	at java.base/jdk.internal.reflect.NativeMethodAccessorImpl.invoke0(Native Method)
	at java.base/jdk.internal.reflect.NativeMethodAccessorImpl.invoke(NativeMethodAccessorImpl.java:62)
	at java.base/jdk.internal.reflect.DelegatingMethodAccessorImpl.invoke(DelegatingMethodAccessorImpl.java:43)
	at java.base/java.lang.reflect.Method.invoke(Method.java:566)
	at org.testng.internal.MethodInvocationHelper.invokeMethod(MethodInvocationHelper.java:85)
	at org.testng.internal.Invoker.invokeMethod(Invoker.java:639)
	at org.testng.internal.Invoker.invokeTestMethod(Invoker.java:816)
	at org.testng.internal.Invoker.invokeTestMethods(Invoker.java:1124)
	at org.testng.internal.TestMethodWorker.invokeTestMethods(TestMethodWorker.java:125)
	at org.testng.internal.TestMethodWorker.run(TestMethodWorker.java:108)
	at org.testng.TestRunner.privateRun(TestRunner.java:774)
	at org.testng.TestRunner.run(TestRunner.java:624)
	at org.testng.SuiteRunner.runTest(SuiteRunner.java:359)
	at org.testng.SuiteRunner.runSequentially(SuiteRunner.java:354)
	at org.testng.SuiteRunner.privateRun(SuiteRunner.java:312)
	at org.testng.SuiteRunner.run(SuiteRunner.java:261)
	at org.testng.SuiteRunnerWorker.runSuite(SuiteRunnerWorker.java:52)
	at org.testng.SuiteRunnerWorker.run(SuiteRunnerWorker.java:86)
	at org.testng.TestNG.runSuitesSequentially(TestNG.java:1191)
	at org.testng.TestNG.runSuitesLocally(TestNG.java:1116)
	at org.testng.TestNG.run(TestNG.java:1024)
	at org.testng.remote.AbstractRemoteTestNG.run(AbstractRemoteTestNG.java:115)
	at org.testng.remote.RemoteTestNG.initAndRun(RemoteTestNG.java:251)
	at org.testng.remote.RemoteTestNG.main(RemoteTestNG.java:77)
]]>
    </failure>
  </testcase> <!-- login -->
  <testcase classname="packageTwo.PackageTwo_ClassTwo" name="methonTwo" time="0.001"/>
  <testcase classname="packageTwo.PackageTwo_ClassTwo" name="methonThree" time="0.0"/>
  <testcase classname="packageTwo.PackageTwo_ClassTwo" name="methonFour" time="0.0"/>
  <testcase classname="packageTwo.PackageTwo_ClassTwo" name="methonFive" time="0.002"/>
</testsuite> <!-- Default test -->
